Workbook

Sheet Dashboard
A1: QC SCENARIO PLANNING DASHBOARD - MULTI-RESOURCE
A3: KEY METRICS OVERVIEW
A4: Total Team Size | B4: =Resources!B11 -> 5 | C4: members
A5: Total Weekly Capacity | B5: =Resources!B12 -> 160 | C5: hours
A6: Average Hourly Rate | B6: =Resources!B13 -> 60 | C6: $
A7: Active Projects | B7: =COUNTA(Projects!A4:A8) -> 3 | C7: projects
A8: Total Projects Hours | B8: =Projects!Q9 -> 71 | C8: hours
A9: Active Tasks | B9: =Tasks!Z10 -> 2 | C9: tasks
A10: Total Task Hours | B10: =Tasks!Z5 -> 240 | C10: hours
A11: Avg Project Completion | B11: =Projects!Q10 -> 0.54929577 | C11: %
A12: Avg Task Completion | B12: =Tasks!Z7 -> 0.84375 | C12: %
A14: RESOURCE UTILIZATION ANALYSIS | I14: PROJECT MULTI-RESOURCE BREAKDOWN
A15: Resource | B15: Level | C15: Weekly Capacity | D15: Project Hours | E15: Active Task Hrs | F15: Total Allocated | G15: Utilization % | I15: Project | J15: Total Hours | K15: Completion % | L15: Status
A16: =Resources!A5 -> Basel | B16: =Resources!B5 -> Senior | C16: =Resources!G5 -> 40 | D16: =SUMIF(Projects!$D$4:$D$8,A16,Projects!$E$4:$E$8)+SUMIF(Projects!$H$4:$H$8,A16,Projects!$I$4:$I$8)+SUMIF(Projects!$L$4:$L$8,A16,Projects!$M$4:$M$8)+SUMIF(Projects!$P$4:$P$8,A16,Projects!$Q$4:$Q$8) -> 0 | E16: =SUMIFS(Tasks!$H$4:$H$12,Tasks!$G$4:$G$12,A16,Tasks!$D$4:$D$12,"Backlog")+SUMIFS(Tasks!$H$4:$H$12,Tasks!$G$4:$G$12,A16,Tasks!$D$4:$D$12,"In Progress")+SUMIFS(Tasks!$K$4:$K$12,Tasks!$J$4:$J$12,A16,Tasks!$D$4:$D$12,"Backlog")+SUMIFS(Tasks!$K$4:$K$12,Tasks!$J$4:$J$12,A16,Tasks!$D$4:$D$12,"In Progress") -> 0 | F16: =D16+E16 -> 0 | G16: =F16/C16 -> 0 | I16: =Projects!B4 -> CST | J16: =Projects!D4 -> 71 | K16: =Projects!G4 -> 0.64788732 | L16: =Projects!J4 -> At Risk
A17: =Resources!A6 -> Belal | B17: =Resources!B6 -> Mid | C17: =Resources!G6 -> 40 | D17: =SUMIF(Projects!$D$4:$D$8,A17,Projects!$E$4:$E$8)+SUMIF(Projects!$H$4:$H$8,A17,Projects!$I$4:$I$8)+SUMIF(Projects!$L$4:$L$8,A17,Projects!$M$4:$M$8)+SUMIF(Projects!$P$4:$P$8,A17,Projects!$Q$4:$Q$8) -> 0 | E17: =SUMIFS(Tasks!$H$4:$H$12,Tasks!$G$4:$G$12,A17,Tasks!$D$4:$D$12,"Backlog")+SUMIFS(Tasks!$H$4:$H$12,Tasks!$G$4:$G$12,A17,Tasks!$D$4:$D$12,"In Progress")+SUMIFS(Tasks!$K$4:$K$12,Tasks!$J$4:$J$12,A17,Tasks!$D$4:$D$12,"Backlog")+SUMIFS(Tasks!$K$4:$K$12,Tasks!$J$4:$J$12,A17,Tasks!$D$4:$D$12,"In Progress") -> 8 | F17: =D17+E17 -> 8 | G17: =F17/C17 -> 0.2 | I17: =Projects!B5 -> FRA | J17: =Projects!D5 -> 0 | K17: =Projects!G5 -> 0 | L17: =Projects!J5 -> No Tasks
A18: =Resources!A7 -> Mahmoud | B18: =Resources!B7 -> Junior | C18: =Resources!G7 -> 40 | D18: =SUMIF(Projects!$D$4:$D$8,A18,Projects!$E$4:$E$8)+SUMIF(Projects!$H$4:$H$8,A18,Projects!$I$4:$I$8)+SUMIF(Projects!$L$4:$L$8,A18,Projects!$M$4:$M$8)+SUMIF(Projects!$P$4:$P$8,A18,Projects!$Q$4:$Q$8) -> 0 | E18: =SUMIFS(Tasks!$H$4:$H$12,Tasks!$G$4:$G$12,A18,Tasks!$D$4:$D$12,"Backlog")+SUMIFS(Tasks!$H$4:$H$12,Tasks!$G$4:$G$12,A18,Tasks!$D$4:$D$12,"In Progress")+SUMIFS(Tasks!$K$4:$K$12,Tasks!$J$4:$J$12,A18,Tasks!$D$4:$D$12,"Backlog")+SUMIFS(Tasks!$K$4:$K$12,Tasks!$J$4:$J$12,A18,Tasks!$D$4:$D$12,"In Progress") -> 3 | F18: =D18+E18 -> 3 | G18: =F18/C18 -> 0.075 | I18: =Projects!B6 -> PPO | J18: =Projects!D6 -> 8 | K18: =Projects!G6 -> 1 | L18: =Projects!J6 -> Complete
A19: =Resources!A8 -> Hany | B19: =Resources!B8 -> Junior | C19: =Resources!G8 -> 40 | D19: =SUMIF(Projects!$D$4:$D$8,A19,Projects!$E$4:$E$8)+SUMIF(Projects!$H$4:$H$8,A19,Projects!$I$4:$I$8)+SUMIF(Projects!$L$4:$L$8,A19,Projects!$M$4:$M$8)+SUMIF(Projects!$P$4:$P$8,A19,Projects!$Q$4:$Q$8) -> 0 | E19: =SUMIFS(Tasks!$H$4:$H$12,Tasks!$G$4:$G$12,A19,Tasks!$D$4:$D$12,"Backlog")+SUMIFS(Tasks!$H$4:$H$12,Tasks!$G$4:$G$12,A19,Tasks!$D$4:$D$12,"In Progress")+SUMIFS(Tasks!$K$4:$K$12,Tasks!$J$4:$J$12,A19,Tasks!$D$4:$D$12,"Backlog")+SUMIFS(Tasks!$K$4:$K$12,Tasks!$J$4:$J$12,A19,Tasks!$D$4:$D$12,"In Progress") -> 0 | F19: =D19+E19 -> 0 | G19: =F19/C19 -> 0 | I19: =Projects!B8 | J19: =Projects!D8 | K19: =Projects!G8 | L19: =Projects!J8
A20: =Resources!A4 -> Gebril | B20: =Resources!B4 -> TL | C20: =Resources!G4 -> 40 | D20: =SUMIF(Projects!$D$4:$D$8,A20,Projects!$E$4:$E$8)+SUMIF(Projects!$H$4:$H$8,A20,Projects!$I$4:$I$8)+SUMIF(Projects!$L$4:$L$8,A20,Projects!$M$4:$M$8)+SUMIF(Projects!$P$4:$P$8,A20,Projects!$Q$4:$Q$8) -> 0 | E20: =SUMIFS(Tasks!$H$4:$H$12,Tasks!$G$4:$G$12,A20,Tasks!$D$4:$D$12,"Backlog")+SUMIFS(Tasks!$H$4:$H$12,Tasks!$G$4:$G$12,A20,Tasks!$D$4:$D$12,"In Progress")+SUMIFS(Tasks!$K$4:$K$12,Tasks!$J$4:$J$12,A20,Tasks!$D$4:$D$12,"Backlog")+SUMIFS(Tasks!$K$4:$K$12,Tasks!$J$4:$J$12,A20,Tasks!$D$4:$D$12,"In Progress") -> 0 | F20: =D20+E20 -> 0 | G20: =F20/C20 -> 0
A23: PROJECT PORTFOLIO STATUS
A24: Project | B24: Task Hrs Est | C24: Task Hrs Done | D24: Completion % | E24: Tasks | F24: Status | J24: TASK STATUS SUMMARY
A25: =Projects!B4 -> CST | B25: =Projects!D4 -> 71 | C25: =Projects!F4 -> 46 | D25: =Projects!G4 -> 0.64788732 | E25: =Projects!H4&"/"&Projects!I4 -> 3/9 | F25: =Projects!J4 -> At Risk | J25: Status | K25: Count
A26: =Projects!B5 -> FRA | B26: =Projects!D5 -> 0 | C26: =Projects!F5 -> 0 | D26: =Projects!G5 -> 0 | E26: =Projects!H5&"/"&Projects!I5 -> 0/0 | F26: =Projects!J5 -> No Tasks | J26: Done | K26: =COUNTIF(Tasks!$D$4:$D$50,"Done") -> 4
A27: =Projects!B6 -> PPO | B27: =Projects!D6 -> 8 | C27: =Projects!F6 -> 8 | D27: =Projects!G6 -> 1 | E27: =Projects!H6&"/"&Projects!I6 -> 1/1 | F27: =Projects!J6 -> Complete | J27: In Progress | K27: =COUNTIF(Tasks!$D$4:$D$50,"In Progress") -> 2
J28: Backlog | K28: =COUNTIF(Tasks!$D$4:$D$50,"Backlog") -> 4
J29: Cancelled | K29: =COUNTIF(Tasks!$D$4:$D$50,"Cancelled") -> 0
J31: PROJECT COMPLETION
J32: Project | K32: Completion %
J33: =Projects!B4 -> CST | K33: =Projects!G4 -> 0.64788732
J34: =Projects!B5 -> FRA | K34: =Projects!G5 -> 0
J35: =Projects!B6 -> PPO | K35: =Projects!G6 -> 1
J36: RESOURCE HOURS BREAKDOWN
J37: Resource | K37: Project Hrs | L37: Active Task Hrs | M37: Total
J38: Basel | K38: =D16 -> 0 | L38: =E16 -> 0 | M38: =K38+L38 -> 0
J39: Belal | K39: =D17 -> 0 | L39: =E17 -> 8 | M39: =K39+L39 -> 8
J40: Mahmoud | K40: =D18 -> 0 | L40: =E18 -> 3 | M40: =K40+L40 -> 3
J41: Hany | K41: =D19 -> 0 | L41: =E19 -> 0 | M41: =K41+L41 -> 0
J42: Gebril | K42: =D20 -> 0 | L42: =E20 -> 0 | M42: =K42+L42 -> 0
J43: TASKS BY PROJECT
J44: Project | K44: Done | L44: In Progress | M44: Backlog
J45: =Projects!B4 -> CST | K45: =COUNTIFS(Tasks!$B$4:$B$50,Projects!$A$4,Tasks!$D$4:$D$50,"Done") -> 3 | L45: =COUNTIFS(Tasks!$B$4:$B$50,Projects!$A$4,Tasks!$D$4:$D$50,"In Progress") -> 2 | M45: =COUNTIFS(Tasks!$B$4:$B$50,Projects!$A$4,Tasks!$D$4:$D$50,"Backlog") -> 4
...

Sheet Projects
A1: PROJECT PORTFOLIO - TASK-DRIVEN TRACKING
A2: Projects are containers that aggregate their tasks. All hours and completion calculated from Tasks sheet.
A3: Project ID | B3: Project Name | C3: Total Weight | D3: Task Hrs Est | E3: Task Hrs Actual | F3: Task Hrs Done | G3: Completion % | H3: Tasks Done | I3: Tasks Total | J3: Status | K3: Priority | L3: Start Date | M3: Target Date
A4: PRJ-001 | B4: CST | C4: 1 | D4: =SUMIF(Tasks!$B$4:$B$50,A4,Tasks!$M$4:$M$50) -> 71 | E4: =SUMIF(Tasks!$B$4:$B$50,A4,Tasks!$N$4:$N$50) -> 46 | F4: =SUMIFS(Tasks!$N$4:$N$50,Tasks!$B$4:$B$50,A4,Tasks!$D$4:$D$50,"Done") -> 46 | G4: =IF(D4>0,F4/D4,0) -> 0.64788732 | H4: =COUNTIFS(Tasks!$B$4:$B$50,A4,Tasks!$D$4:$D$50,"Done") -> 3 | I4: =COUNTIF(Tasks!$B$4:$B$50,A4) -> 9 | J4: =IF(I4=0,"No Tasks",IF(H4=I4,"Complete",IF(G4>=0.7,"On Track","At Risk"))) -> At Risk | K4: 46023 | L4: =K4+D4/8 -> 46031.875 | M4: 46096
A5: PRJ-002 | B5: FRA | C5: 1 | D5: =SUMIF(Tasks!$B$4:$B$50,A5,Tasks!$M$4:$M$50) -> 0 | E5: =SUMIF(Tasks!$B$4:$B$50,A5,Tasks!$N$4:$N$50) -> 0 | F5: =SUMIFS(Tasks!$N$4:$N$50,Tasks!$B$4:$B$50,A5,Tasks!$D$4:$D$50,"Done") -> 0 | G5: =IF(D5>0,F5/D5,0) -> 0 | H5: =COUNTIFS(Tasks!$B$4:$B$50,A5,Tasks!$D$4:$D$50,"Done") -> 0 | I5: =COUNTIF(Tasks!$B$4:$B$50,A5) -> 0 | J5: =IF(I5=0,"No Tasks",IF(H5=I5,"Complete",IF(G5>=0.7,"On Track","At Risk"))) -> No Tasks | K5: 46023 | L5: =K5+D5/8 -> 46023
A6: PRJ-003 | B6: PPO | C6: 1 | D6: =SUMIF(Tasks!$B$4:$B$50,A6,Tasks!$M$4:$M$50) -> 8 | E6: =SUMIF(Tasks!$B$4:$B$50,A6,Tasks!$N$4:$N$50) -> 8 | F6: =SUMIFS(Tasks!$N$4:$N$50,Tasks!$B$4:$B$50,A6,Tasks!$D$4:$D$50,"Done") -> 8 | G6: =IF(D6>0,F6/D6,0) -> 1 | H6: =COUNTIFS(Tasks!$B$4:$B$50,A6,Tasks!$D$4:$D$50,"Done") -> 1 | I6: =COUNTIF(Tasks!$B$4:$B$50,A6) -> 1 | J6: =IF(I6=0,"No Tasks",IF(H6=I6,"Complete",IF(G6>=0.7,"On Track","At Risk"))) -> Complete | K6: 46034 | L6: =K6+D6/8 -> 46035 | M6: 13-01-2025
P9: Projects Total Hours | Q9: =Sum(D4:D5) -> 71
P10: Avg.Completion | Q10: =AVERAGE(G4:G8) -> 0.54929577

Sheet Assumptions
A1: QC SCENARIO PLANNING - ASSUMPTIONS
A3: RESOURCE PRODUCTIVITY RATES
A4: Resource Level | B4: Project Rate (%/hr) | C4: Task Rate (%/hr)
A5: Senior QC | B5: 0.03 | C5: 0.06
A6: Mid QC | B6: 0.02 | C6: 0.04
A7: Junior QC | B7: 0.01 | C7: 0.02
A8: TL | B8: 0.05 | C8: 0.1
A9: PROJECT WEIGHT DISTRIBUTION
A10: Resource Level | B10: Weight Fill % | C10: Description
A11: Senior QC | B11: 0.7 | C11: Senior fills 70% of project weight
A12: Mid QC | B12: 0.5 | C12: Mid fills 50% of project weight
A13: Junior QC | B13: 0.3 | C13: Junior fills 30% of project weight
A14: TL | B14: 0.9 | C14: TL fills 90% of project weight
A15: WORKING HOURS ASSUMPTIONS
A16: Hours per Day | B16: 8
A17: Working Days per Week | B17: 5

Sheet Resources
A1: QC RESOURCES
A3: Resource Name | B3: Level | C3: Hourly Rate ($) | D3: Project Rate (%/hr) | E3: Task Rate (%/hr) | F3: Weight Fill | G3: Availability (hrs/week)
A4: Gebril | B4: TL | C4: 85 | D4: =Assumptions!$B$8 -> 0.05 | E4: =Assumptions!$C$8 -> 0.1 | F4: =Assumptions!$B$14 -> 0.9 | G4: 40
A5: Basel | B5: Senior | C5: 85 | D5: =Assumptions!$B$5 -> 0.03 | E5: =Assumptions!$C$5 -> 0.06 | F5: =Assumptions!$B$11 -> 0.7 | G5: 40
A6: Belal | B6: Mid | C6: 65 | D6: =Assumptions!$B$6 -> 0.02 | E6: =Assumptions!$C$6 -> 0.04 | F6: =Assumptions!$B$12 -> 0.5 | G6: 40
A7: Mahmoud | B7: Junior | C7: 45 | D7: =Assumptions!$B$7 -> 0.01 | E7: =Assumptions!$C$7 -> 0.02 | F7: =Assumptions!$B$13 -> 0.3 | G7: 40
A8: Hany | B8: Junior | C8: 45 | D8: =Assumptions!$B$7 -> 0.01 | E8: =Assumptions!$C$7 -> 0.02 | F8: =Assumptions!$B$13 -> 0.3 | G8: 40
A10: TEAM SUMMARY
A11: Total Team Size: | B11: =COUNTA(A4:A8) -> 5
A12: Total Weekly Hours: | B12: =SUM(G5:G8) -> 160
A13: Average Hourly Rate: | B13: =AVERAGE(C5:C8) -> 60

Sheet Tasks
A1: DYNAMIC TASK MANAGEMENT - STATUS & PERFORMANCE TRACKING
A2: Track task status (Backlog/In Progress/Done), actual hours, and performance. Only ACTIVE tasks count toward utilization.
A3: Task ID | B3: Project ID | C3: Task Name | D3: Status | E3: Required Hours | F3: Days | G3: Resource 1 | H3: R1 Est Hrs | I3: R1 Actual Hrs | J3: Resource 2 | K3: R2 Est Hrs | L3: R2 Actual Hrs | M3: Total Est | N3: Total Actual | O3: Est Completion | P3: Actual Completion | Q3: Hours Variance | R3: Efficiency % | S3: Start Date | T3: Due Date | U3: Completed Date | V3: Priority | W3: Dependencies | Y3: TASK SUMMARY
A4: TSK-001 | B4: PRJ-001 | C4: Mobile View Testing Cycle | D4: Done | E4: 32 | F4: =E4/Assumptions!$B$16 -> 4 | G4: Mahmoud | H4: 20 | I4: 16 | J4: Hany | K4: 20 | L4: 20 | M4: =H4+K4 -> 40 | N4: =I4+L4 -> 36 | O4: =M4/E4 -> 1.25 | P4: =N4/E4 -> 1.125 | Q4: =N4-M4 -> -4 | R4: =IF(N4>0,M4/N4,0) -> 1.1111111 | S4: 46033 | T4: 46037 | U4: 46035 | V4: Medium | W4: None | Y4: Total Tasks: | Z4: =COUNTA(A4:A80) -> 10 | AB4: HOW IT WORKS:
A5: TSK-002 | B5: PRJ-001 | C5: حذف اسم المفوض | D5: Done | E5: 8 | F5: =E5/Assumptions!$B$16 -> 1 | G5: Belal | H5: 8 | I5: 2 | J5: Hany | K5: 4 | L5: 4 | M5: =H5+K5 -> 12 | N5: 8 | O5: =M5/E5 -> 1.5 | P5: =N5/E5 -> 1 | Q5: =N5-M5 -> -4 | R5: =IF(N5>0,M5/N5,0) -> 1.5 | S5: 46033 | T5: 46033 | U5: 46033 | V5: Medium | W5: None | Y5: Total Required Hours: | Z5: =SUM(E4:E80) -> 240 | AB5: Required Hours = Total work needed (e.g., 24 hrs = 3 days)
A6: TSK-003 | B6: PRJ-001 | C6: missing punch updates | D6: In Progress | E6: 2 | F6: =E6/Assumptions!$B$16 -> 0.25 | G6: Mahmoud | H6: 3 | M6: =H6+K6 -> 3 | N6: =I6+L6 -> 0 | O6: =M6/E6 -> 1.5 | P6: =N6/E6 -> 0 | Q6: =N6-M6 -> -3 | R6: =IF(N6>0,M6/N6,0) -> 0 | S6: 46037 | T6: 46037 | V6: High | W6: None | Y6: Total Allocated Hours: | Z6: =SUM(M4:M80) -> 79 | AB6: Allocated Hours = Sum of hours from Resource 1 + Resource 2
A7: TSK-004 | B7: PRJ-001 | C7: إجازة متعاقدين | D7: Backlog | E7: 16 | F7: =E7/Assumptions!$B$16 -> 2 | M7: =H7+K7 -> 0 | N7: =I7+L7 -> 0 | O7: =M7/E7 -> 0 | P7: =N7/E7 -> 0 | Q7: =N7-M7 -> 0 | R7: =IF(N7>0,M7/N7,0) -> 0 | V7: High | W7: None | Y7: Average Completion: | Z7: =AVERAGE(O4:O80) -> 0.84375 | AB7: Completion % = Allocated / Required (100% = done)
A8: TSK-005 | B8: PRJ-001 | C8: إشعارات + تقرير تعليم الأبناء | D8: In Progress | E8: 8 | F8: =E8/Assumptions!$B$16 -> 1 | G8: Belal | H8: 8 | M8: =H8+K8 -> 8 | N8: =I8+L8 -> 0 | O8: =M8/E8 -> 1 | P8: =N8/E8 -> 0 | Q8: =N8-M8 -> -8 | R8: =IF(N8>0,M8/N8,0) -> 0 | S8: 46037 | T8: 46037 | V8: High | W8: None | Y8: Tasks Complete: | Z8: =COUNTIF(D4:D80,"Done") -> 4 | AB8: Hours Remaining = Required - Allocated (negative = surplus)
A9: TSK-006 | B9: PRJ-001 | C9: إشعارات السحب الطلب | D9: Done | E9: 8 | F9: =E9/Assumptions!$B$16 -> 1 | G9: Belal | H9: 8 | I9: 2 | M9: =H9+K9 -> 8 | N9: =I9+L9 -> 2 | O9: =M9/E9 -> 1 | P9: =N9/E9 -> 0.25 | Q9: =N9-M9 -> -6 | R9: =IF(N9>0,M9/N9,0) -> 4 | S9: 46033 | T9: 46033 | U9: 46033 | V9: Medium | W9: None | Y9: Tasks Cancel: | Z9: =COUNTIF(D4:D80,"Cancelled") -> 0 | AB9: Days = Required Hours / 8 (from Assumptions)
A10: TSK-007 | B10: PRJ-001 | C10: طلب خارج الدوام متعقدين طلب دفع خارج الدوام متعقدين طلب إلغاء خارج الدوام متعقدين | D10: Backlog | E10: 42 | F10: =E10/Assumptions!$B$16 -> 5.25 | M10: =H10+K10 -> 0 | N10: =I10+L10 -> 0 | O10: =M10/E10 -> 0 | P10: =N10/E10 -> 0 | Q10: =N10-M10 -> 0 | R10: =IF(N10>0,M10/N10,0) -> 0 | S10: 46034 | T10: 46048 | V10: Critical | W10: None | Y10: Task Active: | Z10: =COUNTIF(D4:D82,"In Progress") -> 2
A11: TSK-008 | B11: PRJ-003 | C11: Portal | Law Services Testing Cycle | D11: Done | E11: 16 | F11: =E11/Assumptions!$B$16 -> 2 | G11: Gebril | H11: 8 | I11: 8 | M11: =H11+K11 -> 8 | N11: =I11+L11 -> 8 | O11: =M11/E11 -> 0.5 | P11: =N11/E11 -> 0.5 | Q11: =N11-M11 -> 0 | R11: =IF(N11>0,M11/N11,0) -> 1 | S11: 46034 | T11: 46035 | U11: 46034 | V11: Critical | W11: None
A12: TSK-009 | B12: PRJ-001 | C12: عدم الاستفادة من الخدمات | D12: Backlog | E12: 80 | F12: =E12/Assumptions!$B$16 -> 10 | M12: =H12+K12 -> 0 | N12: =I12+L12 -> 0 | Q12: =N12-M12 -> 0 | R12: =IF(N12>0,M12/N12,0) -> 0 | V12: Critical | W12: None
A13: TSk-010 | B13: PRJ-001 | C13: خدمة إلغاء سلفة شخصية (سداد مبكر) | D13: Backlog | E13: 28 | F13: =E13/Assumptions!$B$16 -> 3.5 | M13: =H13+K13 -> 0 | N13: =I13+L13 -> 0 | Q13: =N13-M13 -> 0 | R13: =IF(N13>0,M13/N13,0) -> 0 | S13: 46044 | T13: 46050 | V13: High | W13: None
F14: =E14/Assumptions!$B$16 -> 0 | M14: =H14+K14 -> 0 | N14: =I14+L14 -> 0 | Q14: =N14-M14 -> 0 | R14: =IF(N14>0,M14/N14,0) -> 0
F15: =E15/Assumptions!$B$16 -> 0 | M15: =H15+K15 -> 0 | N15: =I15+L15 -> 0 | Q15: =N15-M15 -> 0 | R15: =IF(N15>0,M15/N15,0) -> 0
F16: =E16/Assumptions!$B$16 -> 0 | M16: =H16+K16 -> 0 | N16: =I16+L16 -> 0 | Q16: =N16-M16 -> 0 | R16: =IF(N16>0,M16/N16,0) -> 0
F17: =E17/Assumptions!$B$16 -> 0 | M17: =H17+K17 -> 0 | N17: =I17+L17 -> 0 | Q17: =N17-M17 -> 0 | R17: =IF(N17>0,M17/N17,0) -> 0
F18: =E18/Assumptions!$B$16 -> 0 | M18: =H18+K18 -> 0 | N18: =I18+L18 -> 0 | Q18: =N18-M18 -> 0 | R18: =IF(N18>0,M18/N18,0) -> 0
F19: =E19/Assumptions!$B$16 -> 0 | M19: =H19+K19 -> 0 | N19: =I19+L19 -> 0 | Q19: =N19-M19 -> 0 | R19: =IF(N19>0,M19/N19,0) -> 0
F20: =E20/Assumptions!$B$16 -> 0 | M20: =H20+K20 -> 0 | N20: =I20+L20 -> 0 | Q20: =N20-M20 -> 0 | R20: =IF(N20>0,M20/N20,0) -> 0
F21: =E21/Assumptions!$B$16 -> 0 | M21: =H21+K21 -> 0 | N21: =I21+L21 -> 0 | Q21: =N21-M21 -> 0 | R21: =IF(N21>0,M21/N21,0) -> 0
F22: =E22/Assumptions!$B$16 -> 0 | M22: =H22+K22 -> 0 | N22: =I22+L22 -> 0 | Q22: =N22-M22 -> 0 | R22: =IF(N22>0,M22/N22,0) -> 0
F23: =E23/Assumptions!$B$16 -> 0 | M23: =H23+K23 -> 0 | N23: =I23+L23 -> 0 | Q23: =N23-M23 -> 0 | R23: =IF(N23>0,M23/N23,0) -> 0
F24: =E24/Assumptions!$B$16 -> 0 | M24: =H24+K24 -> 0 | N24: =I24+L24 -> 0 | Q24: =N24-M24 -> 0 | R24: =IF(N24>0,M24/N24,0) -> 0
F25: =E25/Assumptions!$B$16 -> 0 | M25: =H25+K25 -> 0 | N25: =I25+L25 -> 0 | Q25: =N25-M25 -> 0 | R25: =IF(N25>0,M25/N25,0) -> 0
... F50: =E50/Assumptions!$B$16 -> 0 | M50: =H50+K50 -> 0 | N50: =I50+L50 -> 0 | Q50: =N50-M50 -> 0 | R50: =IF(N50>0,M50/N50,0) -> 0
F51: =E51/Assumptions!$B$16 -> 0
F52: =E52/Assumptions!$B$16 -> 0
F53: =E53/Assumptions!$B$16 -> 0
